<?xml version="1.0"?>
<sdf version="1.5">
												
<model name = "stewart">
	<plugin name="joint_controller" filename="libjoint_controller.so"/>

	<joint name = "piston1_prismatic_joint" type = "prismatic" >
		<parent> piston1_cylinder_link </parent>
		<child> piston1_shaft_link </child>
		<pose> 0 0 0 0 0 0 </pose>
		<axis>
			<xyz> 0 0 1 </xyz>
			<limit>
				<lower> 0 </lower>
				<upper> 0.1962285247891133 </upper>
				<velocity> 1 </velocity>
			</limit>
		</axis>
	</joint>


	<joint name = "piston3_prismatic_joint" type = "prismatic" >
		<parent> piston3_cylinder_link </parent>
		<child> piston3_shaft_link </child>
		<pose> 0 0 0 0 0 0 </pose>
		<axis>
			<xyz> 0 0 1 </xyz>
			<limit>
				<lower> 0 </lower>
				<upper> 0.1962285247891133 </upper>
				<velocity> 1 </velocity>
			</limit>
		</axis>
	</joint>


	<joint name = "piston5_prismatic_joint" type = "prismatic" >
		<parent> piston5_cylinder_link </parent>
		<child> piston5_shaft_link </child>
		<pose> 0 0 0 0 0 0 </pose>
		<axis> 
			<xyz> 0 0 1 </xyz>
			<limit>
				<lower> 0 </lower>
				<upper> 0.1962285247891133 </upper>
				<velocity> 1 </velocity>
			</limit>
		</axis>
	</joint>


	<joint name = "bottom_ball1_joint" type = "revolute" >
		<parent> base_link </parent>
		<child> bottom_ball1_link </child>
		<pose> 0 0 0 0 0 0 </pose>
		<axis> 
			<xyz> 0 1 0 </xyz>
			<limit>
				<lower> -0.786 </lower>
				<upper> 0.786 </upper>
				<velocity> 0.1 </velocity>
			</limit>
		</axis>
	</joint>


	<joint name = "bottom_ball3_joint" type = "revolute" >
		<parent> base_link </parent>
		<child> bottom_ball3_link </child>
		<pose> 0 0 0 0 0 0 </pose>
		<axis> 
			<xyz> 0 1 0 </xyz>
			<limit>
				<lower> -0.786 </lower>
				<upper> 0.786 </upper>
				<velocity> 0.1 </velocity>
			</limit>
		</axis>
	</joint>


	<joint name = "bottom_ball5_joint" type = "revolute" >
		<parent> base_link </parent>
		<child> bottom_ball5_link </child>
		<pose> 0 0 0 0 0 0 </pose>
		<axis> 
			<xyz> 0 1 0 </xyz>
			<limit>
				<lower> -0.786 </lower>
				<upper> 0.786 </upper>
				<velocity> 0.1 </velocity>
			</limit>
		</axis>
	</joint>


	<joint name = "top_ball1_joint" type = "revolute2" >
		<parent> platform_link </parent>
		<child> top_ball1_link </child>
		<pose> 0 0 0 0 0 0 </pose>
		<axis> 
			<xyz> 0 1 0 </xyz>
			<limit>
				<lower> -0.786 </lower>
				<upper> 0.786 </upper>
				<velocity> 0.1 </velocity>
			</limit>
		</axis>
		<axis2> 
			<xyz> 0 0 1 </xyz>
			<limit>
				<lower> -0.786 </lower>
				<upper> 0.786 </upper>
				<velocity> 0.1 </velocity>
			</limit>
		</axis2>
	</joint>


	<joint name = "top_ball3_joint" type = "revolute2" >
		<parent> platform_link </parent>
		<child> top_ball3_link </child>
		<pose> 0 0 0 0 0 0 </pose>
		<axis> 
			<xyz> 0 1 0 </xyz>
			<limit>
				<lower> -0.786 </lower>
				<upper> 0.786 </upper>
				<velocity> 0.1 </velocity>
			</limit>
		</axis>
		<axis2> 
			<xyz> 0 0 1 </xyz>
			<limit>
				<lower> -0.786 </lower>
				<upper> 0.786 </upper>
				<velocity> 0.1 </velocity>
			</limit>
		</axis2>
	</joint>


	<joint name = "top_ball5_joint" type = "revolute2" >
		<parent> platform_link </parent>
		<child> top_ball5_link </child>
		<pose> 0 0 0 0 0 0 </pose>
		<axis> 
			<xyz> 0 1 0 </xyz>
			<limit>
				<lower> -0.786 </lower>
				<upper> 0.786 </upper>
				<velocity> 0.1 </velocity>
			</limit>
		</axis>
		<axis2> 
			<xyz> 0 0 1 </xyz>
			<limit>
				<lower> -0.786 </lower>
				<upper> 0.786 </upper>
				<velocity> 0.1 </velocity>
			</limit>
		</axis2>
	</joint>


	<joint name = "piston1_bottom_pitch_joint" type = "revolute" >
		<parent> bottom_ball1_link </parent>
		<child> piston1_cylinder_link </child>
		<pose> 0 0 -0.09811426239455664 0 0 0 </pose>
		<axis> 
			<xyz> 1 0 0 </xyz>
			<limit>
				<lower> -0.786 </lower>
				<upper> 0.786 </upper>
			</limit>
		</axis>
	</joint>


	<joint name = "piston3_bottom_pitch_joint" type = "revolute" >
		<parent> bottom_ball3_link </parent>
		<child> piston3_cylinder_link </child>
		<pose> 0 0 -0.09811426239455664 0 0 0 </pose>
		<axis> 
			<xyz> 1 0 0 </xyz>
			<limit>
				<lower> -0.786 </lower>
				<upper> 0.786 </upper>
			</limit>
		</axis>
	</joint>


	<joint name = "piston5_bottom_pitch_joint" type = "revolute" >
		<parent> bottom_ball5_link </parent>
		<child> piston5_cylinder_link </child>
		<pose> 0 0 -0.09811426239455664 0 0 0 </pose>
		<axis> 
			<xyz> 1 0 0 </xyz>
			<limit>
				<lower> -0.786 </lower>
				<upper> 0.786 </upper>
			</limit>
		</axis>
	</joint>

	<joint name = "piston1_top_pitch_joint" type = "revolute" >
		<parent> top_ball1_link </parent>
		<child> piston1_shaft_link </child>
		<pose> 0 0 0.09811426239455664 0 0 0 </pose>
		<axis> 
			<xyz> 1 0 0 </xyz>
			<limit>
				<lower> -0.786 </lower>
				<upper> 0.786 </upper>
			</limit>
		</axis>
	</joint>

	<joint name = "piston3_top_pitch_joint" type = "revolute" >
		<parent> top_ball3_link </parent>
		<child> piston3_shaft_link </child>
		<pose> 0 0 0.09811426239455664 0 0 0 </pose>
		<axis> 
			<xyz> 1 0 0 </xyz>
			<limit>
				<lower> -0.786 </lower>
				<upper> 0.786 </upper>
			</limit>
		</axis>
	</joint>


	<joint name = "piston5_top_pitch_joint" type = "revolute" >
		<parent> top_ball5_link </parent>
		<child> piston5_shaft_link </child>
		<pose> 0 0 0.09811426239455664 0 0 0 </pose>
		<axis> 
			<xyz> 1 0 0 </xyz>
			<limit>
				<lower> -0.786 </lower>
				<upper> 0.786 </upper>
			</limit>
		</axis>
	</joint>


	<link name = "base_link" >
		<pose> 0 0 0.005 0 0 0 </pose>
		<inertial>
			<mass> 1000.0 </mass>
			<inertia>
				<ixx> 1.4145833333333333 </ixx>
				<ixy> 0.0 </ixy>
				<ixz> 0.0</ixz>
				<iyy> 1.4145833333333333 </iyy>
				<iyz> 0.0 </iyz>
				<izz> 2.8125 </izz>
			</inertia>
		</inertial>

		<visual name = "base_link_visual" >
			<geometry>
				<cylinder>
					<radius> 0.075 </radius>
					<length> 0.01 </length>
				</cylinder>
			</geometry>
			<material>
				<script>
					<uri>file://media/materials/scripts/gazebo.material</uri>
					<name>Gazebo/Black</name>
				</script>
			</material>
		</visual>

		<collision name = "base_link_collision" >
			<geometry>
				<cylinder>
					<radius> 0.075 </radius>
					<length> 0.01 </length>
				</cylinder>
			</geometry>
		</collision>
	</link>

	<link name = "platform_link" >
		<pose> 0 0 0.20500000000000002 0 0 0 </pose>
		<inertial>
			<mass> 1.0 </mass>
			<inertia>
				<ixx> 0.0014115833333333333 </ixx>
				<ixy> 0.0 </ixy>
				<ixz> 0.0</ixz>
				<iyy> 0.0014115833333333333 </iyy>
				<iyz> 0.0 </iyz>
				<izz> 0.0028125 </izz>
			</inertia>
		</inertial>

		<visual name = "base_link_visual" >
			<geometry>
				<cylinder>
					<radius> 0.075 </radius>
					<length> 0.008 </length>
				</cylinder>
			</geometry>
			<material>
				<script>
					<uri>file://media/materials/scripts/gazebo.material</uri>
					<name>Gazebo/Red</name>
				</script>
			</material>
		</visual>

		<collision name = "base_link_collision" >
			<geometry>
				<cylinder>
					<radius> 0.075 </radius>
					<length> 0.008 </length>
				</cylinder>
			</geometry>
		</collision>
	</link>

	<link name = "bottom_ball1_link" >
		<pose> -0.008085221650768307 0.05898838182945814 0.01 0 0 1.571 </pose>
		<inertial>
			<mass> 0.1 </mass>
			<inertia>
				<ixx> 0.0 </ixx>
				<ixy> 0.0 </ixy>
				<ixz> 0.0 </ixz>
				<iyy> 0.0 </iyy>
				<iyz> 0.0 </iyz>
				<izz> 0.0 </izz>
			</inertia>
		</inertial>

		<visual name = "bottom_ball1_link_visual" >
			<geometry>
				<sphere>
					<radius> 0.008" </radius>
				</sphere>
			</geometry>
		</visual>

		<collision name = "bottom_ball1_link_collision" >
			<geometry>
				<sphere>
					<radius> 0.008" </radius>
				</sphere>
			</geometry>
		</collision>
	</link>

	
	<link name = "bottom_ball3_link" >
		<pose> 0.05511443246494093 -0.022525526277258547 0.01 0 0 0 </pose>
		<inertial>
			<mass> 0.1 </mass>
			<inertia>
				<ixx> 0.0 </ixx>
				<ixy> 0.0 </ixy>
				<ixz> 0.0 </ixz>
				<iyy> 0.0 </iyy>
				<iyz> 0.0 </iyz>
				<izz> 0.0 </izz>
			</inertia>
		</inertial>

		<visual name = "bottom_ball3_link_visual" >
			<geometry>
				<sphere>
					<radius> 0.008" </radius>
				</sphere>
			</geometry>
		</visual>

		<collision name = "bottom_ball3_link_collision" >
			<geometry>
				<sphere>
					<radius> 0.008" </radius>
				</sphere>
			</geometry>
		</collision>
	</link>

	<link name = "bottom_ball5_link" >
		<pose> -0.04712336056605641 -0.03639215422259912 0.01 0 0 -1.571 </pose>
		<inertial>
			<mass> 0.1 </mass>
			<inertia>
				<ixx> 0.0 </ixx>
				<ixy> 0.0 </ixy>
				<ixz> 0.0 </ixz>
				<iyy> 0.0 </iyy>
				<iyz> 0.0 </iyz>
				<izz> 0.0 </izz>
			</inertia>
		</inertial>

		<visual name = "bottom_ball5_link_visual" >
			<geometry>
				<sphere>
					<radius> 0.008" </radius>
				</sphere>
			</geometry>
		</visual>

		<collision name = "bottom_ball5_link_collision" >
			<geometry>
				<sphere>
					<radius> 0.008" </radius>
				</sphere>
			</geometry>
		</collision>
	</link>

	<link name = "top_ball1_link" >
		<pose> -0.008085221650768307 0.05898838182945814 0.201 0 0 1.571 </pose>
		<inertial>
			<mass> 0.1 </mass>
			<inertia>
				<ixx> 0.0 </ixx>
				<ixy> 0.0 </ixy>
				<ixz> 0.0 </ixz>
				<iyy> 0.0 </iyy>
				<iyz> 0.0 </iyz>
				<izz> 0.0 </izz>
			</inertia>
		</inertial>

		<visual name = "bottom_ball1_link_visual" >
			<geometry>
				<sphere>
					<radius> 0.004" </radius>
				</sphere>
			</geometry>
		</visual>

		<collision name = "bottom_ball1_link_collision" >
			<geometry>
				<sphere>
					<radius> 0.004" </radius>
				</sphere>
			</geometry>
		</collision>
	</link>

	<link name = "top_ball3_link" >
		<pose> 0.05511443246494093 -0.022525526277258547 0.201 0 0 0 </pose>
		<inertial>
			<mass> 0.1 </mass>
			<inertia>
				<ixx> 0.0 </ixx>
				<ixy> 0.0 </ixy>
				<ixz> 0.0 </ixz>
				<iyy> 0.0 </iyy>
				<iyz> 0.0 </iyz>
				<izz> 0.0 </izz>
			</inertia>
		</inertial>

		<visual name = "bottom_ball1_link_visual" >
			<geometry>
				<sphere>
					<radius> 0.004" </radius>
				</sphere>
			</geometry>
		</visual>

		<collision name = "bottom_ball1_link_collision" >
			<geometry>
				<sphere>
					<radius> 0.004" </radius>
				</sphere>
			</geometry>
		</collision>
	</link>

	<link name = "top_ball5_link" >
		<pose> -0.04712336056605641 -0.03639215422259912 0.201 0 0 -1.571 </pose>
		<inertial>
			<mass> 0.1 </mass>
			<inertia>
				<ixx> 0.0 </ixx>
				<ixy> 0.0 </ixy>
				<ixz> 0.0 </ixz>
				<iyy> 0.0 </iyy>
				<iyz> 0.0 </iyz>
				<izz> 0.0 </izz>
			</inertia>
		</inertial>

		<visual name = "bottom_ball1_link_visual" >
			<geometry>
				<sphere>
					<radius> 0.004" </radius>
				</sphere>
			</geometry>
		</visual>

		<collision name = "bottom_ball1_link_collision" >
			<geometry>
				<sphere>
					<radius> 0.004" </radius>
				</sphere>
			</geometry>
		</collision>
	</link>

	<link name = "piston1_cylinder_link" >
		<pose> -0.008085221650768307 0.05898838182945814 0.10500000000000001 0 0 1.571 </pose>
		<inertial>
			<mass> 0.1 </mass>
			<inertia>
				<ixx> 0.0 </ixx>
				<ixy> 0.0 </ixy>
				<ixz> 0.0 </ixz>
				<iyy> 0.0 </iyy>
				<iyz> 0.0 </iyz>
				<izz> 0.0 </izz>
			</inertia>
		</inertial>

		<visual name = "piston1_cylinder_link_visual" >
			<geometry>
				<cylinder>
					<radius> 0.008 </radius>
					<length> 0.1962285247891133" </length>
				</cylinder>
			</geometry>
			<material>
				<script>
					<uri>file://media/materials/scripts/gazebo.material</uri>
					<name>Gazebo/Red</name>
				</script>
			</material>
		</visual>

		<collision name = "piston1_link_collision" >
			<geometry>
				<cylinder>
					<radius> 0.008 </radius>
					<length> 0.1962285247891133" </length>
				</cylinder>
			</geometry>
		</collision>
	</link>

	<link name = "piston3_cylinder_link" >
		<pose> 0.05511443246494093 -0.022525526277258547 0.10500000000000001 0 0 0 </pose>
		<inertial>
			<mass> 0.1 </mass>
			<inertia>
				<ixx> 0.0 </ixx>
				<ixy> 0.0 </ixy>
				<ixz> 0.0 </ixz>
				<iyy> 0.0 </iyy>
				<iyz> 0.0 </iyz>
				<izz> 0.0 </izz>
			</inertia>
		</inertial>

		<visual name = "piston3_cylinder_link_visual" >
			<geometry>
				<cylinder>
					<radius> 0.008 </radius>
					<length> 0.1962285247891133" </length>
				</cylinder>
			</geometry>
			<material>
				<script>
					<uri>file://media/materials/scripts/gazebo.material</uri>
					<name>Gazebo/Red</name>
				</script>
			</material>
		</visual>

		<collision name = "piston3_link_collision" >
			<geometry>
				<cylinder>
					<radius> 0.008 </radius>
					<length> 0.1962285247891133" </length>
				</cylinder>
			</geometry>
		</collision>
	</link>


	<link name = "piston5_cylinder_link" >
		<pose> -0.04712336056605641 -0.03639215422259912 0.10500000000000001 0 0 -1.571 </pose>
		<inertial>
			<mass> 0.1 </mass>
			<inertia>
				<ixx> 0.0 </ixx>
				<ixy> 0.0 </ixy>
				<ixz> 0.0 </ixz>
				<iyy> 0.0 </iyy>
				<iyz> 0.0 </iyz>
				<izz> 0.0 </izz>
			</inertia>
		</inertial>

		<visual name = "piston5_cylinder_link_visual" >
			<geometry>
				<cylinder>
					<radius> 0.008 </radius>
					<length> 0.1962285247891133" </length>
				</cylinder>
			</geometry>
			<material>
				<script>
					<uri>file://media/materials/scripts/gazebo.material</uri>
					<name>Gazebo/Red</name>
				</script>
			</material>
		</visual>

		<collision name = "piston5_link_collision" >
			<geometry>
				<cylinder>
					<radius> 0.008 </radius>
					<length> 0.1962285247891133" </length>
				</cylinder>
			</geometry>
		</collision>
	</link>

	<link name = "piston1_shaft_link" >
		<pose> -0.008085221650768307 0.05898838182945814 0.10500000000000001 0 0 1.571 </pose>
		<inertial>
			<mass> 0.1 </mass>
			<inertia>
				<ixx> 0.0 </ixx>
				<ixy> 0.0 </ixy>
				<ixz> 0.0 </ixz>
				<iyy> 0.0 </iyy>
				<iyz> 0.0 </iyz>
				<izz> 0.0 </izz>
			</inertia>
		</inertial>

		<visual name = "piston1_shaft_visual" >
			<geometry>
				<cylinder>
					<radius> 0.004" </radius>
					<length> 0.1962285247891133" </length>
				</cylinder>
			</geometry>
			<material>
				<script>
					<uri>file://media/materials/scripts/gazebo.material</uri>
					<name>Gazebo/Black</name>
				</script>
			</material>
		</visual>

		<collision name = "piston1_shaft_collision" >
			<geometry>
				<cylinder>
					<radius> 0.004" </radius>
					<length> 0.1962285247891133" </length>
				</cylinder>
			</geometry>
		</collision>
	</link>

	<link name = "piston3_shaft_link" >
		<pose> 0.05511443246494093 -0.022525526277258547 0.10500000000000001 0 0 0 </pose>
		<inertial>
			<mass> 0.1 </mass>
			<inertia>
				<ixx> 0.0 </ixx>
				<ixy> 0.0 </ixy>
				<ixz> 0.0 </ixz>
				<iyy> 0.0 </iyy>
				<iyz> 0.0 </iyz>
				<izz> 0.0 </izz>
			</inertia>
		</inertial>

		<visual name = "piston3_shaft_visual" >
			<geometry>
				<cylinder>
					<radius> 0.004" </radius>
					<length> 0.1962285247891133" </length>
				</cylinder>
			</geometry>
			<material>
				<script>
					<uri>file://media/materials/scripts/gazebo.material</uri>
					<name>Gazebo/Black</name>
				</script>
			</material>
		</visual>

		<collision name = "piston3_shaft_collision" >
			<geometry>
				<cylinder>
					<radius> 0.004" </radius>
					<length> 0.1962285247891133" </length>
				</cylinder>
			</geometry>
		</collision>
	</link>

	<link name = "piston5_shaft_link" >
		<pose> -0.04712336056605641 -0.03639215422259912 0.10500000000000001 0 0 -1.571 </pose>
		<inertial>
			<mass> 0.1 </mass>
			<inertia>
				<ixx> 0.0 </ixx>
				<ixy> 0.0 </ixy>
				<ixz> 0.0 </ixz>
				<iyy> 0.0 </iyy>
				<iyz> 0.0 </iyz>
				<izz> 0.0 </izz>
			</inertia>
		</inertial>

		<visual name = "piston5_shaft_visual" >
			<geometry>
				<cylinder>
					<radius> 0.004" </radius>
					<length> 0.1962285247891133" </length>
				</cylinder>
			</geometry>
			<material>
				<script>
					<uri>file://media/materials/scripts/gazebo.material</uri>
					<name>Gazebo/Black</name>
				</script>
			</material>
		</visual>

		<collision name = "piston5_shaft_collision" >
			<geometry>
				<cylinder>
					<radius> 0.004" </radius>
					<length> 0.1962285247891133" </length>
				</cylinder>
			</geometry>
		</collision>
	</link>

</model>
</sdf>
